Workbook

Sheet Overview
A1: SmartFlow NLEX - Sprint to 100%
A2: Sep 29 - Oct 8, 2026 | deadline Oct 9 | 10:00-22:30 daily | built from CP-Grp4_AcceptanceCriteria.pdf, last updated 2026-09-28 22:59
A4: THIS PLAN IS DRIVEN BY WEIGHT, NOT BY SUBTASK COUNT
A5: Your acceptance criteria file weights every task. A 2.8% task and a 0.3% task are not the same day's work,
A6: so the Priority Board is sorted by weight points still to gain. Clear the top of that list and the number moves.
A7: Blue cells are yours. Everything black is a formula.
A9: WHERE THE PROJECT STANDS
A10: Track | B10: Allocated % | C10: Actual % | D10: Gap % | E10: Complete | F10: Note
A11: SYSTEM | B11: 90 | C11: 61.049 | D11: =B11-C11 | E11: =IFERROR(C11/B11,0) | F11: 286 tasks. Target: 90% by Tue Oct 6.
A12: MANUSCRIPT | B12: 10 | C12: 0.769 | D12: =B12-C12 | E12: =IFERROR(C12/B12,0) | F12: 39 tasks, mostly 'Document X' riding each module. Target: 10% by Thu Oct 8.
A13: TOTAL | B13: =SUM(B11:B12) | C13: =SUM(C11:C12) | D13: =B13-C13 | E13: =IFERROR(C13/B13,0) | F13: 38.2 weight points to find in ten days.
A15: THE FIVE THAT MATTER MOST
A16: Three tasks sit at 0.000%: INCIDENTFC (2.832), PRESCRIBE (2.517) and RAG (2.517). With MODEVAL (2.518 to gain) and the MOD-BE/MOD-ANA manuscript blocks (2.564 each), these six carry 15.5 of the 38.2 points. Nothing else on the board moves the number as fast.
A19: TEAM
A20: Member | B20: Code pts to gain | C20: MS pts to gain | D20: Total | E20: Share | F20: Owns
A21: Kiarra | B21: =SUMIF('Priority Board'!D:D,A21,'Priority Board'!I:I) | C21: =SUMIF(Manuscript!$D$16:$D$41,A21,Manuscript!$M$16:$M$41) | D21: =B21+C21 | E21: =IFERROR(D21/$D$25,0) | F21: CORE (HOST, ENV, REPO), AUTH, MAINT, DATAUP, UIUX. Lightest code gap by design, so she carries the Ch.1-3 revision pass and the MOD-FE manuscript block.
A22: Hans | B22: =SUMIF('Priority Board'!D:D,A22,'Priority Board'!I:I) | C22: =SUMIF(Manuscript!$D$16:$D$41,A22,Manuscript!$M$16:$M$41) | D22: =B22+C22 | E22: =IFERROR(D22/$D$25,0) | F22: MOD-ANA's model side - PRESCRIBE, MODEVAL, TRAFFICFC, DATAPREP - plus DATA, CACHE, ETL, SUSTAIN, EMISSDESC, and the vehicle-dynamics half of the agent simulation. Heaviest load, and owns the 3.11 corrections.
A23: Jertz | B23: =SUMIF('Priority Board'!D:D,A23,'Priority Board'!I:I) | C23: =SUMIF(Manuscript!$D$16:$D$41,A23,Manuscript!$M$16:$M$41) | D23: =B23+C23 | E23: =IFERROR(D23/$D$25,0) | F23: INCIDENTFC (0%), INCIDENT, INCIDENTDESC, MAPCOMP, AUDIT, and the scenario and validation half of the agent simulation. Becomes the regression pass after code freeze, and owns 3.13 SQA.
A24: Ysa | B24: =SUMIF('Priority Board'!D:D,A24,'Priority Board'!I:I) | C24: =SUMIF(Manuscript!$D$16:$D$41,A24,Manuscript!$M$16:$M$41) | D24: =B24+C24 | E24: =IFERROR(D24/$D$25,0) | F24: RAG (0%), SANDBOX, REALTIME, UPLOAD and mobile. The simulation model moved to Hans and Jertz; she keeps the API and UI around it, which frees a day for figures and MOD-FE support.
A25: TOTAL | B25: =SUM(B21:B24) | C25: =SUM(C21:C24) | D25: =SUM(D21:D24)
A26: Code points come from the Priority Board by task owner. Manuscript points are attributed to whoever WRITES each of the 26 sections, with every subtask taking an equal share of its module's allocation - the module owner is not always the writer, which is why Ysa previously showed zero.
A28: - Your other tracker shows MOD-MOB with 33 subtasks. The acceptance criteria file has no MOD-MOB at all, and the five modules in it sum to 90%. Confirm which document is graded - if mobile is assessed, this plan is missing a module.
A29: - The two trackers disagree on totals (254 vs 286 tasks, 74.8% vs 67.8% of SYSTEM). This plan follows the acceptance criteria file because it is weighted and dated most recently.

Sheet Priority Board
A1: Priority Board - every task by weight still to gain
A2: Three ways a task progresses, and they agree: tick Status = Done on a daily block and Blocks done rises, type a figure into Actual %, or put Y in Done? to count the whole task at once. Done? overrides the rest.
A4: Task ID | B4: Description | C4: Module | D4: Owner | E4: Alloc % | F4: Actual % | G4: Done? | H4: Counted % | I4: Points to gain | J4: % done | K4: Target window | L4: Status | M4: Blocks done | N4: Blocks planned
A5: AUTH | B5: Authentication & Session Management (frontend) | C5: MOD-FE | D5: Kiarra | E5: 1.888 | F5: 1.259 | G5: N | H5: =IF(UPPER(G5)="Y",E5,IF(N5=0,F5,F5+(E5-F5)*M5/N5)) | I5: =E5-H5 | J5: =IFERROR(H5/E5,0) | K5: Oct 5 - Oct 6 | L5: =IF(H5>=E5,"Done",IF(H5>0,"In progress","Not started")) | M5: =COUNTIFS(Kiarra!$I:$I,"*;"&$A5&";*",Kiarra!$H:$H,"Done")+COUNTIFS(Hans!$I:$I,"*;"&$A5&";*",Hans!$H:$H,"Done")+COUNTIFS(Jertz!$I:$I,"*;"&$A5&";*",Jertz!$H:$H,"Done")+COUNTIFS(Ysa!$I:$I,"*;"&$A5&";*",Ysa!$H:$H,"Done") | N5: =COUNTIF(Kiarra!$I:$I,"*;"&$A5&";*")+COUNTIF(Hans!$I:$I,"*;"&$A5&";*")+COUNTIF(Jertz!$I:$I,"*;"&$A5&";*")+COUNTIF(Ysa!$I:$I,"*;"&$A5&";*")
A6: TRAFFIC | B6: Traffic Overview Dashboard (frontend) | C6: MOD-FE | D6: Hans | E6: 3.147 | F6: 2.832 | G6: N | H6: =IF(UPPER(G6)="Y",E6,IF(N6=0,F6,F6+(E6-F6)*M6/N6)) | I6: =E6-H6 | J6: =IFERROR(H6/E6,0) | K6: Oct 5 - Oct 6 | L6: =IF(H6>=E6,"Done",IF(H6>0,"In progress","Not started")) | M6: =COUNTIFS(Kiarra!$I:$I,"*;"&$A6&";*",Kiarra!$H:$H,"Done")+COUNTIFS(Hans!$I:$I,"*;"&$A6&";*",Hans!$H:$H,"Done")+COUNTIFS(Jertz!$I:$I,"*;"&$A6&";*",Jertz!$H:$H,"Done")+COUNTIFS(Ysa!$I:$I,"*;"&$A6&";*",Ysa!$H:$H,"Done") | N6: =COUNTIF(Kiarra!$I:$I,"*;"&$A6&";*")+COUNTIF(Hans!$I:$I,"*;"&$A6&";*")+COUNTIF(Jertz!$I:$I,"*;"&$A6&";*")+COUNTIF(Ysa!$I:$I,"*;"&$A6&";*")
A7: INCIDENT | B7: Incident Data API Endpoints (frontend) | C7: MOD-FE | D7: Jertz | E7: 2.832 | F7: 2.517 | G7: N | H7: =IF(UPPER(G7)="Y",E7,IF(N7=0,F7,F7+(E7-F7)*M7/N7)) | I7: =E7-H7 | J7: =IFERROR(H7/E7,0) | K7: Oct 5 - Oct 6 | L7: =IF(H7>=E7,"Done",IF(H7>0,"In progress","Not started")) | M7: =COUNTIFS(Kiarra!$I:$I,"*;"&$A7&";*",Kiarra!$H:$H,"Done")+COUNTIFS(Hans!$I:$I,"*;"&$A7&";*",Hans!$H:$H,"Done")+COUNTIFS(Jertz!$I:$I,"*;"&$A7&";*",Jertz!$H:$H,"Done")+COUNTIFS(Ysa!$I:$I,"*;"&$A7&";*",Ysa!$H:$H,"Done") | N7: =COUNTIF(Kiarra!$I:$I,"*;"&$A7&";*")+COUNTIF(Hans!$I:$I,"*;"&$A7&";*")+COUNTIF(Jertz!$I:$I,"*;"&$A7&";*")+COUNTIF(Ysa!$I:$I,"*;"&$A7&";*")
A8: SANDBOX | B8: AI Traffic Sandbox API (frontend) | C8: MOD-FE | D8: Ysa | E8: 2.832 | F8: 1.888 | G8: N | H8: =IF(UPPER(G8)="Y",E8,IF(N8=0,F8,F8+(E8-F8)*M8/N8)) | I8: =E8-H8 | J8: =IFERROR(H8/E8,0) | K8: Oct 5 - Oct 6 | L8: =IF(H8>=E8,"Done",IF(H8>0,"In progress","Not started")) | M8: =COUNTIFS(Kiarra!$I:$I,"*;"&$A8&";*",Kiarra!$H:$H,"Done")+COUNTIFS(Hans!$I:$I,"*;"&$A8&";*",Hans!$H:$H,"Done")+COUNTIFS(Jertz!$I:$I,"*;"&$A8&";*",Jertz!$H:$H,"Done")+COUNTIFS(Ysa!$I:$I,"*;"&$A8&";*",Ysa!$H:$H,"Done") | N8: =COUNTIF(Kiarra!$I:$I,"*;"&$A8&";*")+COUNTIF(Hans!$I:$I,"*;"&$A8&";*")+COUNTIF(Jertz!$I:$I,"*;"&$A8&";*")+COUNTIF(Ysa!$I:$I,"*;"&$A8&";*")
A9: MAINT | B9: Maintenance Scheduler API (frontend) | C9: MOD-FE | D9: Kiarra | E9: 2.517 | F9: 1.888 | G9: N | H9: =IF(UPPER(G9)="Y",E9,IF(N9=0,F9,F9+(E9-F9)*M9/N9)) | I9: =E9-H9 | J9: =IFERROR(H9/E9,0) | K9: Oct 5 - Oct 6 | L9: =IF(H9>=E9,"Done",IF(H9>0,"In progress","Not started")) | M9: =COUNTIFS(Kiarra!$I:$I,"*;"&$A9&";*",Kiarra!$H:$H,"Done")+COUNTIFS(Hans!$I:$I,"*;"&$A9&";*",Hans!$H:$H,"Done")+COUNTIFS(Jertz!$I:$I,"*;"&$A9&";*",Jertz!$H:$H,"Done")+COUNTIFS(Ysa!$I:$I,"*;"&$A9&";*",Ysa!$H:$H,"Done") | N9: =COUNTIF(Kiarra!$I:$I,"*;"&$A9&";*")+COUNTIF(Hans!$I:$I,"*;"&$A9&";*")+COUNTIF(Jertz!$I:$I,"*;"&$A9&";*")+COUNTIF(Ysa!$I:$I,"*;"&$A9&";*")
A10: MAPCOMP | B10: Map Comparison API (frontend) | C10: MOD-FE | D10: Jertz | E10: 2.832 | F10: 1.573 | G10: N | H10: =IF(UPPER(G10)="Y",E10,IF(N10=0,F10,F10+(E10-F10)*M10/N10)) | I10: =E10-H10 | J10: =IFERROR(H10/E10,0) | K10: Oct 3 - Oct 5 | L10: =IF(H10>=E10,"Done",IF(H10>0,"In progress","Not started")) | M10: =COUNTIFS(Kiarra!$I:$I,"*;"&$A10&";*",Kiarra!$H:$H,"Done")+COUNTIFS(Hans!$I:$I,"*;"&$A10&";*",Hans!$H:$H,"Done")+COUNTIFS(Jertz!$I:$I,"*;"&$A10&";*",Jertz!$H:$H,"Done")+COUNTIFS(Ysa!$I:$I,"*;"&$A10&";*",Ysa!$H:$H,"Done") | N10: =COUNTIF(Kiarra!$I:$I,"*;"&$A10&";*")+COUNTIF(Hans!$I:$I,"*;"&$A10&";*")+COUNTIF(Jertz!$I:$I,"*;"&$A10&";*")+COUNTIF(Ysa!$I:$I,"*;"&$A10&";*")
A11: SUSTAIN | B11: Sustainability & Emissions API (frontend) | C11: MOD-FE | D11: Hans | E11: 2.517 | F11: 1.259 | G11: N | H11: =IF(UPPER(G11)="Y",E11,IF(N11=0,F11,F11+(E11-F11)*M11/N11)) | I11: =E11-H11 | J11: =IFERROR(H11/E11,0) | K11: Oct 4 - Oct 5 | L11: =IF(H11>=E11,"Done",IF(H11>0,"In progress","Not started")) | M11: =COUNTIFS(Kiarra!$I:$I,"*;"&$A11&";*",Kiarra!$H:$H,"Done")+COUNTIFS(Hans!$I:$I,"*;"&$A11&";*",Hans!$H:$H,"Done")+COUNTIFS(Jertz!$I:$I,"*;"&$A11&";*",Jertz!$H:$H,"Done")+COUNTIFS(Ysa!$I:$I,"*;"&$A11&";*",Ysa!$H:$H,"Done") | N11: =COUNTIF(Kiarra!$I:$I,"*;"&$A11&";*")+COUNTIF(Hans!$I:$I,"*;"&$A11&";*")+COUNTIF(Jertz!$I:$I,"*;"&$A11&";*")+COUNTIF(Ysa!$I:$I,"*;"&$A11&";*")
A12: DATAUP | B12: Data Management & Upload Page | C12: MOD-FE | D12: Kiarra | E12: 2.517 | F12: 2.517 | G12: N | H12: =IF(UPPER(G12)="Y",E12,IF(N12=0,F12,F12+(E12-F12)*M12/N12)) | I12: =E12-H12 | J12: =IFERROR(H12/E12,0) | K12: Oct 5 - Oct 6 | L12: =IF(H12>=E12,"Done",IF(H12>0,"In progress","Not started")) | M12: =COUNTIFS(Kiarra!$I:$I,"*;"&$A12&";*",Kiarra!$H:$H,"Done")+COUNTIFS(Hans!$I:$I,"*;"&$A12&";*",Hans!$H:$H,"Done")+COUNTIFS(Jertz!$I:$I,"*;"&$A12&";*",Jertz!$H:$H,"Done")+COUNTIFS(Ysa!$I:$I,"*;"&$A12&";*",Ysa!$H:$H,"Done") | N12: =COUNTIF(Kiarra!$I:$I,"*;"&$A12&";*")+COUNTIF(Hans!$I:$I,"*;"&$A12&";*")+COUNTIF(Jertz!$I:$I,"*;"&$A12&";*")+COUNTIF(Ysa!$I:$I,"*;"&$A12&";*")
A13: AUDIT | B13: Audit Log API (frontend) | C13: MOD-FE | D13: Jertz | E13: 2.203 | F13: 1.573 | G13: N | H13: =IF(UPPER(G13)="Y",E13,IF(N13=0,F13,F13+(E13-F13)*M13/N13)) | I13: =E13-H13 | J13: =IFERROR(H13/E13,0) | K13: Oct 5 - Oct 6 | L13: =IF(H13>=E13,"Done",IF(H13>0,"In progress","Not started")) | M13: =COUNTIFS(Kiarra!$I:$I,"*;"&$A13&";*",Kiarra!$H:$H,"Done")+COUNTIFS(Hans!$I:$I,"*;"&$A13&";*",Hans!$H:$H,"Done")+COUNTIFS(Jertz!$I:$I,"*;"&$A13&";*",Jertz!$H:$H,"Done")+COUNTIFS(Ysa!$I:$I,"*;"&$A13&";*",Ysa!$H:$H,"Done") | N13: =COUNTIF(Kiarra!$I:$I,"*;"&$A13&";*")+COUNTIF(Hans!$I:$I,"*;"&$A13&";*")+COUNTIF(Jertz!$I:$I,"*;"&$A13&";*")+COUNTIF(Ysa!$I:$I,"*;"&$A13&";*")
A14: AUTH | B14: Authentication & Session Management (backend/API) | C14: MOD-BE | D14: Kiarra | E14: 2.517 | F14: 1.573 | G14: N | H14: =IF(UPPER(G14)="Y",E14,IF(N14=0,F14,F14+(E14-F14)*M14/N14)) | I14: =E14-H14 | J14: =IFERROR(H14/E14,0) | K14: Oct 5 - Oct 6 | L14: =IF(H14>=E14,"Done",IF(H14>0,"In progress","Not started")) | M14: =COUNTIFS(Kiarra!$I:$I,"*;"&$A14&";*",Kiarra!$H:$H,"Done")+COUNTIFS(Hans!$I:$I,"*;"&$A14&";*",Hans!$H:$H,"Done")+COUNTIFS(Jertz!$I:$I,"*;"&$A14&";*",Jertz!$H:$H,"Done")+COUNTIFS(Ysa!$I:$I,"*;"&$A14&";*",Ysa!$H:$H,"Done") | N14: =COUNTIF(Kiarra!$I:$I,"*;"&$A14&";*")+COUNTIF(Hans!$I:$I,"*;"&$A14&";*")+COUNTIF(Jertz!$I:$I,"*;"&$A14&";*")+COUNTIF(Ysa!$I:$I,"*;"&$A14&";*")
A15: TRAFFIC | B15: Traffic Overview Dashboard (backend/API) | C15: MOD-BE | D15: Hans | E15: 2.203 | F15: 2.203 | G15: N | H15: =IF(UPPER(G15)="Y",E15,IF(N15=0,F15,F15+(E15-F15)*M15/N15)) | I15: =E15-H15 | J15: =IFERROR(H15/E15,0) | K15: Oct 5 - Oct 6 | L15: =IF(H15>=E15,"Done",IF(H15>0,"In progress","Not started")) | M15: =COUNTIFS(Kiarra!$I:$I,"*;"&$A15&";*",Kiarra!$H:$H,"Done")+COUNTIFS(Hans!$I:$I,"*;"&$A15&";*",Hans!$H:$H,"Done")+COUNTIFS(Jertz!$I:$I,"*;"&$A15&";*",Jertz!$H:$H,"Done")+COUNTIFS(Ysa!$I:$I,"*;"&$A15&";*",Ysa!$H:$H,"Done") | N15: =COUNTIF(Kiarra!$I:$I,"*;"&$A15&";*")+COUNTIF(Hans!$I:$I,"*;"&$A15&";*")+COUNTIF(Jertz!$I:$I,"*;"&$A15&";*")+COUNTIF(Ysa!$I:$I,"*;"&$A15&";*")
A16: INCIDENT | B16: Incident Data API Endpoints (backend/API) | C16: MOD-BE | D16: Jertz | E16: 2.203 | F16: 2.203 | G16: N | H16: =IF(UPPER(G16)="Y",E16,IF(N16=0,F16,F16+(E16-F16)*M16/N16)) | I16: =E16-H16 | J16: =IFERROR(H16/E16,0) | K16: Oct 5 - Oct 6 | L16: =IF(H16>=E16,"Done",IF(H16>0,"In progress","Not started")) | M16: =COUNTIFS(Kiarra!$I:$I,"*;"&$A16&";*",Kiarra!$H:$H,"Done")+COUNTIFS(Hans!$I:$I,"*;"&$A16&";*",Hans!$H:$H,"Done")+COUNTIFS(Jertz!$I:$I,"*;"&$A16&";*",Jertz!$H:$H,"Done")+COUNTIFS(Ysa!$I:$I,"*;"&$A16&";*",Ysa!$H:$H,"Done") | N16: =COUNTIF(Kiarra!$I:$I,"*;"&$A16&";*")+COUNTIF(Hans!$I:$I,"*;"&$A16&";*")+COUNTIF(Jertz!$I:$I,"*;"&$A16&";*")+COUNTIF(Ysa!$I:$I,"*;"&$A16&";*")
... A42: PM | B42: Pm | C42: CORE | D42: Kiarra | E42: 0.944 | F42: 0.944 | G42: N | H42: =IF(UPPER(G42)="Y",E42,IF(N42=0,F42,F42+(E42-F42)*M42/N42)) | I42: =E42-H42 | J42: =IFERROR(H42/E42,0) | K42: - | L42: =IF(H42>=E42,"Done",IF(H42>0,"In progress","Not started")) | M42: =COUNTIFS(Kiarra!$I:$I,"*;"&$A42&";*",Kiarra!$H:$H,"Done")+COUNTIFS(Hans!$I:$I,"*;"&$A42&";*",Hans!$H:$H,"Done")+COUNTIFS(Jertz!$I:$I,"*;"&$A42&";*",Jertz!$H:$H,"Done")+COUNTIFS(Ysa!$I:$I,"*;"&$A42&";*",Ysa!$H:$H,"Done") | N42: =COUNTIF(Kiarra!$I:$I,"*;"&$A42&";*")+COUNTIF(Hans!$I:$I,"*;"&$A42&";*")+COUNTIF(Jertz!$I:$I,"*;"&$A42&";*")+COUNTIF(Ysa!$I:$I,"*;"&$A42&";*")
A43: TOTAL | E43: =SUM(E5:E42) | F43: =SUM(F5:F42) | H43: =SUM(H5:H42) | I43: =SUM(I5:I42)

Sheet Kiarra
A1: Kiarra - daily plan
A2: Three blocks a day. Code from 10:00; the manuscript takes the tail. Column F is what to do, column G is how you know it is finished. Ticking Status = Done credits the task named in Feeds - so the Tracker moves as you work. Blocks marked (overhead) carry no weight in the acceptance criteria.
A4: Date | B4: Day | C4: Block | D4: Track | E4: Task | F4: What to do | G4: Done when | H4: Status | I4: Feeds | J4: Closes
A5: 2026-09-29 | B5: Tue | C5: 10:00 - 14:00 | D5: Code | E5: HOST | F5: Run `npx next build` in Front-End-Dashboard before anything else. It has never been run. Fix every error it reports - type errors, bad imports, missing env vars at build time. | G5: The build completes and writes .next/ with no errors. | H5: Done | I5: ;HOST; | J5: -
C6: 14:00 - 20:30 | D6: Code | E6: HOST | F6: Package the dashboard as a desktop application, not a public website. Two blockers, both recorded in ENVIRONMENTS.md: package.json has no electron-builder "build" block (no appId, file list or icon), and the packaged app loads over file:// which sends Origin: null and is refused by the backend CORS allow-list. Serve out/ on 127.0.0.1 in the packaged app so the origin matches what FRONTEND_ORIGIN already permits. | G6: npm run dist produces an installer that opens on a second machine and fills the Traffic page. | H6: Not started | I6: ;HOST; | J6: -
C7: 20:30 - 22:30 | D7: Manuscript | E7: MS-01 UIUX | F7: Document the design system: the CSS custom-property tokens in globals.css, --page-accent per domain, the dark-mode strategy, and useThemeTokens for charts. | G7: A section exists naming the tokens and showing one before/after of a themed panel. | H7: Done | I7: ;MOD-FE; | J7: ;MS:UIUX;
A8: 2026-09-30 | B8: Wed | C8: 10:00 - 14:00 | D8: Code | E8: ENV | F8: Write .env.example for Back-End and Front-End-Dashboard. Every PG_* part, NEXT_PUBLIC_BACKEND_URL, the Upstash vars. Values blank, comments explaining each. | G8: A new machine can start both apps from the examples alone. | H8: Done | I8: ;ENV; | J8: -
C9: 14:00 - 20:30 | D9: Code | E9: ENV / REPO | F9: ROTATE THE UPSTASH TOKEN - BEFORE THE DEFENSE. Confirmed still outstanding as of 1 Oct; the supporting detail was shared with the team directly rather than recorded here. DO: console.upstash.com -> the Redis DB -> REST API -> Reset token; paste the new value into Back-End/.env (REDIS_REST_URL is unchanged); restart the backend. Do NOT rewrite git history - rotating is sufficient, and a force-push would destroy the six backup-before-*-merge rollback branches. Scratch files deleted and BRANCHING.md written; git status is clean as of the 1 Oct commits. | G9: The new token authenticates, the old one is refused, and the Live Map still fills. git status clean - already met. | H9: In progress | I9: ;REPO; | J9: -
C10: 20:30 - 22:30 | D10: Manuscript | E10: MS-01 ENV + REPO | F10: Document environment configuration and the branching strategy. Note that frontend .env is committed on purpose and backend .env never is. | G10: Both sections written. | H10: Done | I10: ;CORE; | J10: ;MS:ENV;MS:REPO;MS:HOST;
A11: 2026-10-01 | B11: Thu | C11: 10:00 - 14:00 | D11: Code | E11: AUTH | F11: Close the remaining auth subtasks: refresh-token handling so an expired access token renews without logging the user out, and role-based access control on frontend routes. | G11: An expired token refreshes silently; an unauthorised role is redirected. | H11: Done | I11: ;AUTH; | J11: -
C12: 14:00 - 19:30 | D12: Code | E12: AUTH | F12: Test valid login, bad credentials, and session expiry. Capture the results - Jertz needs them for the QA section. All three pass, plus nine more: 12 scenarios in Table 4.2.12 of Chapter4_Auth_Session_Management.md. Valid login issues both tokens (access token lives 3600s) and reaches a protected endpoint; bad credentials return the same message for an unknown account as for a wrong password, so no user enumeration; a refused request refreshes and replays with no re-login. Wrong role returns 403 and is correctly NOT retried. Three QA accounts exist in Supabase on a .test domain - decide whether to keep them for the demo. | G12: Three scenarios pass and are screenshotted. | H12: Done | I12: ;AUTH; | J12: -
C13: 19:30 - 22:30 | D13: Manuscript | E13: MS-01 AUTH | F13: Document the JWT and session-management flow: token lifetimes, refresh path, where the token is stored, how routes are guarded. | G13: Section complete with a flow diagram. | H13: Done | I13: ;MOD-FE; | J13: ;MS:AUTH;
A14: 2026-10-02 | B14: Fri | C14: 10:00 - 14:00 | D14: Code | E14: MAINT | F14: Close the remaining Maintenance Scheduler API subtasks. DONE: DEV-01/02/03 verified; TEST-01 and FIX-01 closed by fixing two defects found while testing - the KM range was not ordered (Km 40 to Km 10 saved cleanly, giving every consumer a negative span), and DELETE ignored rowCount so a missing id answered 200 "Deleted" and wrote an audit entry for a deletion that never happened. MAINT is now 7 of 8 subtasks (2.203 of 2.517). STILL OPEN - UAT-01: the interface must be evaluated by maintenance coordinators who can confirm they can plan and organise roadwork with it. That needs real evaluators, not code. ALSO: the existing "Toll Booth Repair" row is entered as Km 76.25 to 73.23 (reversed) and is in progress - correct it by hand; the new validation stops another but does not repair that one. QA PASS (2 Oct): 24 adversarial checks - boundaries, malformed timestamps, script/SQL payloads, bad ids, invalid status transitions. One more defect found and fixed: a malformed id reached Postgres, which threw, and the service reports every query failure as 'database not reachable', so a typo answered 503 and would have raised an infrastructure alarm. Now 404. OPEN DESIGN GAP: status is never reconciled with the clock. Both rows have windows that closed in August; one still reads in_progress so the page claims 3.0 km 'under work right now' for work that ended 46 days ago, and the other reads scheduled so the tile shows 1 beside 'nothing upcoming'. Fix before any demo. | G14: Every acceptance criterion under MAINT is met. | H14: In progress | I14: ;MAINT; | J14: -
C15: 14:00 - 19:30 | D15: Code | E15: MAINT | F15: Test the scheduler end to end from the UI. 26 checks pass: 16 against the endpoints and 10 driven through the real interface signed in as a Data Analyst - form opens and accepts an entry, it appears in the list, detail panel opens, edit persists, delete asks for confirmation, the row leaves the list and is still gone after a reload. Screenshots in manuscript-figures/ for the QA section. | G15: A maintenance item can be created, edited and removed from the dashboard. | H15: Done | I15: ;MAINT; | J15: -
C16: 19:30 - 22:30 | D16: Manuscript | E16: MS-01 MAINT | F16: Document the maintenance API - endpoints, payloads, how it reaches the dashboard. | G16: Section complete. | H16: Done | I16: ;MOD-BE; | J16: ;MS:MAINT;
A17: 2026-10-03 | B17: Sat | C17: 10:00 - 14:00 | D17: Code | E17: CORE | F17: Migrate ESLint to flat config. DONE 7 Oct. Confirmed broken first: npx eslint . exited 2 with "couldn't find an eslint.config file" - ESLint 9 was declared but configured through .eslintrc.json, which v9 no longer reads. next build lints anyway because Next shims the old format internally, which is why nobody noticed the standalone step had never worked, while 3.13 SQA describes it as part of the process. Added eslint.config.mjs using FlatCompat (eslint-config-next ships no flat entry yet), so the rule set is unchanged - only how it loads. Result: npx eslint . exits 0, 0 errors, 83 warnings. The 3 errors it first reported were require() in electron/main.js and preload.js; Electron loads both as CommonJS by requirement, so the rule is off for electron/** rather than the calls being worked around. FOLLOW-UP: .eslintrc.json is still on disk. It is dead to ESLint 9 but next build may still read it; delete it and re-run a full build to confirm, which needs the dev server stopped. | G17: npx eslint . runs and the error count is zero or triaged. | H17: Done | I17: (overhead) | J17: -
C18: 14:00 - 18:30 | D18: Code | E18: Acceptance file split | F18: Split the acceptance file's repeated task IDs by module. DONE 7 Oct. The row was 18.882 points, not the 3.773 this block assumed - 21% of the entire system weight, owned by nobody. Seven IDs repeat across MOD-FE and MOD-BE at different weights (AUTH is 1.888 on the frontend and 2.517 on the backend, and so on). The PDF does not label which table belongs to which module, so each column was summed and matched against the module totals printed on the same page; all five match to within decimal rounding, so the assignment is evidence, not a guess. The board now carries 38 task rows across MOD-FE/BE/ANA/DB/CORE and no (unmapped) row. NOTE: it totals 89.999, not 90.000. The source states every weight to three decimals and 38 of them do not re-sum exactly; the PDF's own module subtotals add to 90.001. The thousandth was left rather than fudged into a row to make the figure look round. | G18: The (unmapped) row is gone and every task sits under its real module. | H18: Done | I18: (overhead) | J18: -
C19: 18:30 - 22:30 | D19: Manuscript | E19: 3.14 Deployment Plans | F19: Rewrite section 3.14 (p228) against the deployment you actually stood up on Sep 29. The current text describes something untested. | G19: 3.14 matches the real deploy, with the build command and env vars named. | H19: Not started | I19: ;MANUSCRIPT; | J19: ;R07;
A20: GATE 21:00 - the 0% tasks demoable
A21: 2026-10-04 | B21: Sun | C21: 10:00 - 14:00 | D21: Code | E21: Ch4 placeholders | F21: Work the bracketed values through Chapter 4. DONE 8 Oct -> Chapter4_Revised_4.1_Results.md. Every placeholder in 4.1 replaced with a value read from the warehouse or the endpoint that renders the matching panel; 15 computed figures re-checked by arithmetic. Note 1 was right: 5 claims run the WRONG WAY. Holidays are 20 of 21 BELOW baseline (Good Friday -49%), not above. Wet weather raises CRASHES 19.3% but not incidents overall (breakdowns outnumber crashes 8:1 and are slightly lower in wet). Observed jam speed is HIGHER in wet, not lower. Volume champion is Prophet, not LSTM (rank 7 of 8, rejected). At the 90/10 split NOTHING is accepted. Also: incident champion carries an OVERFITTING diagnosis; 9 named analyses are not implemented in the build; the emission strategy panel is hardcoded ILLUSTRATIVE; and non-Waze speed is SYNTHETIC per the warehouse's own evaluation records - that disclosure is not in the draft at all. 16 corrections listed in section 4.1.6. | G21: No bracketed placeholder left in 4.1, and each sentence still says something true. | H21: Done | I21: ;MANUSCRIPT; | J21: ;C07;
C22: 14:00 - 18:30 | D22: Code | E22: MOD-FE | F22: Contrast and accessibility sweep across every page in both themes. DONE 7 Oct, nothing to fix. 10 dashboard pages x light and dark = 20 runs, ~10,000 text-bearing elements scored against the surface each is actually painted on, walking up the tree for transparent backgrounds. Result: 0 elements below 3:1. Theme switching was verified separately rather than assumed - light resolves --bg-body to #eef5fd and dark to #0a1838, with data-theme set on the root - because light and dark returned identical element counts and that would also be the signature of the theme never switching. CAVEAT: 4-6 elements per page sit on a gradient or image and are reported, not scored; a single computed background cannot represent what is behind them. Those need an eye, not a probe. The NLEX Daylight redesign held contrast well - this found nothing to fix. | G22: No text under 3:1 on any dashboard page. | H22: Done | I22: (overhead) | J22: -
C23: 18:30 - 22:30 | D23: Manuscript | E23: 3.7 Mock-ups | F23: Replace the mock-ups in 3.7 with screenshots of what shipped. DONE 8 Oct, via Chapter 4: 32 panels captured live from the running dashboard and embedded, plus the 4 existing figures = 36. MFA blocked this at first - the shell now drops a password-only (aal1) session, so a scripted login appeared to work then silently signed itself out. Enrolled TOTP on a fresh capture account to mint an aal2 session. TWO PANELS IN THE DRAFT NO LONGER EXIST: Secondary Incident Risk and Time to Clear are gone, replaced by Response Time Breakdown and Predicted Median Response Time - those screenshots must be swapped. THREE PANELS PREVIOUSLY CALLED MISSING NOW EXIST: Booth Staffing Plan, Congestion Response Advisory, and the emission strategies, which are now COMPUTED (3.39/0.48/0.33%), not the old hardcoded Strategy A/B/C mock. | G23: Every mock-up is either a real screenshot or labelled as a design-stage artefact. | H23: Done | I23: ;MANUSCRIPT; | J23: ;R05;
A24: 2026-10-05 | B24: Mon | C24: 10:00 - 14:00 | D24: Code | E24: DATAUP | F24: Close the remaining Data Management and Upload Page subtasks. DONE 7 Oct - there were none remaining. The acceptance file already records all 8 DATAUP subtasks complete (2.517 of 2.517), including its UAT-01. What was worth checking is that the page still works after the upload endpoints went behind authenticateToken + data-analyst on 1 Oct: /history, /formats and /retraining all answer 401 without a token and 200 with one, and the page routes every call through lib/api.ts, so it carries the session. No regression. NOTE: UPLOAD (2.203/1.888, the backend half of the same page) is Ysa's, not this block's. | G24: Upload page meets its acceptance criteria. | H24: Done | I24: ;DATAUP; | J24: -
C25: 14:00 - 16:30 | D25: Code | E25: MOD-FE | F25: Final polish pass. Anything cosmetic you have been meaning to fix, do it now - after Oct 6 only defects get touched. | G25: Your own snag list is empty. | H25: Not started | I25: (overhead) | J25: -
C26: 16:30 - 22:30 | D26: Manuscript | E26: 3.7 / 3.8 | F26: Finish 3.7 and revise 3.8 System Generated Outputs (p178) to list the outputs the dashboard actually produces. | G26: Both sections match the built system. | H26: Not started | I26: ;MANUSCRIPT; | J26: ;R06;
A27: 2026-10-06 | B27: Tue | C27: 10:00 - 14:00 | D27: Code | E27: MOD-FE | F27: Close every remaining MOD-FE subtask. This is the last day code changes. | G27: MOD-FE at 100% on the board. | H27: Not started | I27: (overhead) | J27: -
C28: 14:00 - 14:30 | D28: Code | E28: FREEZE | F28: Run the freeze: full build, tag the release, write down the commit hash. Nothing merges after 22:30 except defect fixes. | G28: A tagged commit exists and the build from it is deployed. | H28: Not started | I28: (overhead) | J28: -
C29: 14:30 - 22:30 | D29: Manuscript | E29: 1.4 / 1.5 | F29: Revise 1.4 Purpose and Objectives (p8) and 1.5 Scope and Limitations (p11). State honestly where objective coverage is partial, and restate the data limits: SCTEX hourly gap, the emissions total moving 143k to 188k tonnes. | G29: No claim in Ch.1 that the demo cannot support. | H29: Not started | I29: ;MANUSCRIPT; | J29: ;R10;R04;
A30: GATE 22:30 - SYSTEM 90%, CODE FREEZE
A31: 2026-10-07 | B31: Wed | C31: 10:00 - 14:00 | D31: Code | E31: FIX | F31: Work Jertz's defect list. Highest severity first. Nothing else. | G31: Every Critical and High defect is closed and retested. | H31: Not started | I31: (overhead) | J31: -
C32: 14:00 - 12:30 | D32: Code | E32: FIX | F32: Continue the defect list. | G32: Queue is empty or the remainder is agreed as known issues. | H32: Not started | I32: (overhead) | J32: -
C33: 12:30 - 22:30 | D33: Manuscript | E33: MS-01 DATAUP + MOD-FE | F33: Document the Data Management page in Chapter 4 and close out the MOD-FE manuscript block. | G33: MOD-FE manuscript weight at 100%. | H33: Not started | I33: ;MOD-FE; | J33: ;MS:DATAUP;
A34: 2026-10-08 | B34: Thu | C34: 10:00 - 14:00 | D34: Code | E34: Notes for the Group | F34: Add the Tailwind deviation as item 7 of Notes for the Group, using the convention already applied beneath Figures 4.1.9, 4.1.24 and 4.1.28. | G34: Item 7 written. | H34: Not started | I34: ;MANUSCRIPT; | J34: ;C08;
C35: 14:00 - 10:00 | D35: Code | E35: - | F35: No code today. | G35: - | H35: Not started | I35: (overhead) | J35: -
C36: 10:00 - 22:30 | D36: Manuscript | E36: Manuscript | F36: Full read-through of Chapters 1-5 end to end. Check every figure is placed and captioned, every cross-reference resolves, and the voice is consistent across four authors. | G36: One person has read the whole document in one sitting and the fixes are made. | H36: Not started | I36: ;MANUSCRIPT; | J36: -
A37: GATE 20:00 - manuscript complete

Sheet Hans
A1: Hans - daily plan
A2: Three blocks a day. Code from 10:00; the manuscript takes the tail. Column F is what to do, column G is how you know it is finished. Ticking Status = Done credits the task named in Feeds - so the Tracker moves as you work. Blocks marked (overhead) carry no weight in the acceptance criteria.
A4: Date | B4: Day | C4: Block | D4: Track | E4: Task | F4: What to do | G4: Done when | H4: Status | I4: Feeds | J4: Closes
A5: 2026-09-29 | B5: Tue | C5: 10:00 - 14:00 | D5: Code | E5: PRESCRIBE | F5: Define the optimisation before writing code. For each of the three strategies: what is the objective function, what are the decision variables, what are the constraints, and what data feeds it. Write it on one page. | G5: A one-page spec exists that someone else could implement from. | H5: Not started | I5: ;PRESCRIBE; | J5: -
C6: 14:00 - 20:30 | D6: Code | E6: PRESCRIBE | F6: Build the emissions optimiser. The current Strategy X/Y/Z are hardcoded constants labelled ILLUSTRATIVE in the UI - replace them with a model that reads real corridor data. | G6: The strategies compute from data and change when the inputs change. | H6: Not started | I6: ;PRESCRIBE; | J6: -
C7: 20:30 - 22:30 | D7: Manuscript | E7: TRAFFIC close-out | F7: Three small traffic tasks are unfinished and were scheduled nowhere: TRAFFICFC (0.630 left), TRAFFIC (0.315) and TRAFFICDESC (0.315). All three are near-complete. Close them tonight while they are cheap. | G7: All three at 100% on the Priority Board. | H7: Not started | I7: ;TRAFFICFC;TRAFFIC;TRAFFICDESC; | J7: -
A8: 2026-09-30 | B8: Wed | C8: 10:00 - 14:00 | D8: Code | E8: PRESCRIBE | F8: Build the traffic-side optimiser: booth staffing and congestion response. The panels exist (PrescriptiveTrafficPanels.tsx) - give them a real model behind the API. | G8: Booth staffing recommendations change with volume and time of day. | H8: Not started | I8: ;PRESCRIBE; | J8: -
C9: 14:00 - 20:30 | D9: Code | E9: PRESCRIBE | F9: Wire both optimisers to real endpoints and remove the ILLUSTRATIVE labels once the numbers are real. | G9: No panel on the Prescriptive tabs is showing a hardcoded constant. | H9: Not started | I9: ;PRESCRIBE; | J9: -
C10: 20:30 - 22:30 | D10: Manuscript | E10: MS-01 TRAFFICFC | F10: Document the traffic forecasting model: HoltWinters as champion, how it was selected, and the walk-forward validation. | G10: Section written with the real champion, not LSTM. | H10: Not started | I10: ;MOD-ANA; | J10: ;MS:TRAFFICFC;MS:TRAFFIC;MS:TRAFFICDESC;
A11: 2026-10-01 | B11: Thu | C11: 10:00 - 14:00 | D11: Code | E11: PRESCRIBE | F11: Finish and test. Edge cases: no data for a segment, extreme demand, a closed lane. | G11: PRESCRIBE meets every acceptance criterion. | H11: Not started | I11: ;PRESCRIBE; | J11: -
C12: 14:00 - 19:30 | D12: Code | E12: MODEVAL | F12: Start the model evaluation suite. Assemble every model's holdout metrics in one place: volume, incident, emissions, congestion, event surge. | G12: One table holds every model, its metric, and its holdout window. | H12: Not started | I12: ;MODEVAL; | J12: -
C13: 19:30 - 22:30 | D13: Manuscript | E13: MS-01 PRESCRIBE | F13: Document the prescriptive models - objective, constraints, and how a recommendation is produced. | G13: Section complete. | H13: Not started | I13: ;MOD-ANA; | J13: ;MS:PRESCRIBE;
A14: 2026-10-02 | B14: Fri | C14: 10:00 - 14:00 | D14: Code | E14: MODEVAL | F14: Check holdout discipline on every model. Confirm nothing is scored on data it trained on, and that each forecast window starts after its training data ends. | G14: Every model has a stated train/test split and it holds. | H14: Not started | I14: ;MODEVAL; | J14: -
C15: 14:00 - 19:30 | D15: Code | E15: MODEVAL | F15: Add whatever metrics are missing from the suite. Baseline comparison matters most - a model that cannot beat 'nothing changes' has to be reported as such. | G15: Every model is reported against a named baseline. | H15: Not started | I15: ;MODEVAL; | J15: -
C16: 19:30 - 22:30 | D16: Manuscript | E16: 3.11 champions | F16: Revise 3.11 (p195). The manuscript names champions the pipeline did not choose. Volume is HoltWinters, not LSTM. Incidents are Poisson GLM. Emissions are Polynomial at 6.79% WMAPE. Restate every model table from the dashboard. | G16: No model table in 3.11 disagrees with the dashboard. | H16: Not started | I16: ;MANUSCRIPT; | J16: ;R01;C02;
A17: 2026-10-03 | B17: Sat | C17: 10:00 - 14:00 | D17: Code | E17: MODEVAL | F17: Finish. Every model signed off with its metrics. | G17: MODEVAL at 100%. | H17: Not started | I17: ;MODEVAL; | J17: -
C18: 14:00 - 18:30 | D18: Code | E18: DATAPREP | F18: Close the analytics data preparation subtasks. | G18: DATAPREP at 100%. | H18: Not started | I18: ;DATAPREP; | J18: -
C19: 18:30 - 22:30 | D19: Manuscript | E19: 3.11 event surge | F19: The 1.59x arena uplift was selection on the outcome - it picked the busiest days and then measured them. The defensible figure is 1.16x (CI 1.08-1.29) across 109 calendar events. Correct every occurrence. | G19: No 1.59x remains anywhere in the manuscript. | H19: Not started | I19: ;MANUSCRIPT; | J19: ;R02;C04;
A20: GATE 21:00 - the 0% tasks demoable
A21: 2026-10-04 | B21: Sun | C21: 10:00 - 14:00 | D21: Code | E21: DATA / CACHE | F21: Close the Core Traffic Data Schema and the Redis cache subtasks. | G21: Both tasks at 100%. | H21: Not started | I21: ;DATA; | J21: -
C22: 14:00 - 18:30 | D22: Code | E22: MOD-DB | F22: Load SCTEX into gold.fact_traffic_hourly and gold.fact_emissions_hourly. The data exists - 2,065 rows in gold.daily_emissions_summary, and gold.exit_name_map already maps 'Mabiga' and 'SCTEX Spur Road'. 19 of 20 exits are loaded; SCTEX is the gap. Nothing in this repo writes those tables. | G22: All 20 exits present in both hourly fact tables. | H22: Not started | I22: ;CACHE; | J22: -
C23: 18:30 - 22:30 | D23: Manuscript | E23: 3.9 Data Gathering | F23: Revise 3.9 (p180). CDV/PH Arena now has a full hourly series and the Bocaue proxy is gone - do not describe it. State the SCTEX position as it stands after today. | G23: 3.9 describes the warehouse as it is. | H23: Not started | I23: ;MANUSCRIPT; | J23: ;R03;
A24: 2026-10-05 | B24: Mon | C24: 10:00 - 14:00 | D24: Code | E24: AGENT (model) | F24: Your half of the agent simulation: calibrate it against real corridor behaviour. The sandbox already runs IDM car-following and MOBIL lane changes in ai-sandbox/simulation.ts, and there is a calibration.json with tools/build_calibration.py beside it. Check the IDM parameters reproduce observed speed at observed demand, using gold.fact_traffic_hourly as truth. | G24: At a known hour of demand the sim throughput and mean speed land within a stated tolerance of the measured values, and that tolerance is written down. | H24: Not started | I24: ;AGENT-M; | J24: -
C25: 14:00 - 16:30 | D25: Code | E25: SUSTAIN + EMISSDESC | F25: Close the Sustainability and Emissions API and the emissions descriptive analytics. Both are small - 1.258 and 0.315 points - so they fit one block. | G25: SUSTAIN and EMISSDESC both at 100%. | H25: Not started | I25: ;SUSTAIN; | J25: -
C26: 16:30 - 22:30 | D26: Manuscript | E26: MS-01 SUSTAIN + EMISSDESC | F26: Document the sustainability API and the emissions descriptive analytics. | G26: Both sections written. | H26: Not started | I26: ;MOD-ANA; | J26: ;MS:SUSTAIN;MS:EMISSDESC;MS:DATAPREP;
A27: 2026-10-06 | B27: Tue | C27: 10:00 - 14:00 | D27: Code | E27: MOD-ANA | F27: Close every remaining MOD-ANA subtask. Last day for model changes. | G27: MOD-ANA at 100% on the board. | H27: Not started | I27: ;EMISSDESC; | J27: -
C28: 14:00 - 14:30 | D28: Code | E28: FREEZE | F28: Freeze with Kiarra. Confirm every model the manuscript cites is the one in the tagged build. | G28: Models and manuscript agree at the frozen commit. | H28: Not started | I28: (overhead) | J28: -
C29: 14:30 - 22:30 | D29: Manuscript | E29: 3.10 / 3.12 | F29: Revise 3.10 Presentation of Schema (p192) against the bronze/silver/gold warehouse as built, and 3.12 Tools and Techniques (p216) against what is actually in the repo. | G29: Both sections match reality. | H29: Not started | I29: ;MANUSCRIPT; | J29: ;R09;R11;
A30: GATE 22:30 - SYSTEM 90%, CODE FREEZE
A31: 2026-10-07 | B31: Wed | C31: 10:00 - 14:00 | D31: Code | E31: FIX | F31: Model-side defects from Jertz's QA pass. | G31: Every analytics defect closed. | H31: Not started | I31: (overhead) | J31: -
C32: 14:00 - 12:30 | D32: Code | E32: Ch4 figure decisions | F32: Decide per figure what to do about the descriptive items the build does not have: no Speed-Flow fundamental diagram (Fig 4.1.5) and no Mapbox KDE / Getis-Ord heat layer (Fig 4.1.9). Keep the note, retitle to what shipped, or drop the item. | G32: Each figure is decided and the caption matches the build. | H32: Not started | I32: ;MANUSCRIPT; | J32: ;C10;
C33: 12:30 - 22:30 | D33: Manuscript | E33: MS-01 ETL / CACHE | F33: Document the ETL pipeline and flow, the Redis cache and messaging setup, and the model training results. | G33: MOD-ANA and MOD-DB manuscript blocks complete. | H33: Not started | I33: ;MOD-DB; | J33: ;MS:ETL;MS:CACHE;
A34: 2026-10-08 | B34: Thu | C34: 10:00 - 14:00 | D34: Code | E34: Table 4.1.3 | F34: Populate Table 4.1.3 (record counts before and after cleaning) - every cell is an [n] placeholder. These are countable from the warehouse directly. | G34: Table 4.1.3 has real counts and a retention rate per dataset. | H34: Not started | I34: ;MANUSCRIPT; | J34: ;C06;
C35: 14:00 - 10:00 | D35: Code | E35: Table 4.1.4 | F35: Populate Table 4.1.4 (model benchmarking) from the benchmarking output rather than transcribing. Keep the losing models with Selected = No, as Note 5 of the draft recommends. | G35: Table 4.1.4 matches the benchmark output, champions included. | H35: Not started | I35: ;MANUSCRIPT; | J35: ;C05;
C36: 10:00 - 22:30 | D36: Manuscript | E36: Manuscript | F36: Final numbers check. Every figure in Chapter 4 must match what the dashboard shows at the frozen commit. Where a number moved during the sprint, make sure the old one is gone everywhere. | G36: No figure in the manuscript disagrees with the demo. | H36: Not started | I36: ;MANUSCRIPT; | J36: -
A37: GATE 20:00 - manuscript complete

Sheet Jertz
A1: Jertz - daily plan
A2: Three blocks a day. Code from 10:00; the manuscript takes the tail. Column F is what to do, column G is how you know it is finished. Ticking Status = Done credits the task named in Feeds - so the Tracker moves as you work. Blocks marked (overhead) carry no weight in the acceptance criteria.
A4: Date | B4: Day | C4: Block | D4: Track | E4: Task | F4: What to do | G4: Done when | H4: Status | I4: Feeds | J4: Closes
A5: 2026-09-29 | B5: Tue | C5: 10:00 - 14:00 | D5: Code | E5: INCIDENTFC | F5: CHECK THIS FIRST. The board says 0.000%, but the Incidents Predictive tab already runs a walk-forward forecast with a Poisson GLM champion and full RMSE/MAE/WMAPE/MASE against 4,361 held-out incidents. Open the tab, then read the acceptance criteria for INCIDENTFC and mark which subtasks are genuinely outstanding. | G5: You know whether this is three days of work or an afternoon of sign-off. Tell the team before lunch. | H5: Not started | I5: ;INCIDENTFC; | J5: -
C6: 14:00 - 20:30 | D6: Code | E6: INCIDENTFC | F6: Work whatever is genuinely missing. If the model is built, the gap is likely validation evidence and sign-off rather than modelling. | G6: Each INCIDENTFC subtask is either done or has a dated plan. | H6: Not started | I6: ;INCIDENTFC; | J6: -
C7: 20:30 - 22:30 | D7: Manuscript | E7: INCIDENT close-out | F7: INCIDENT (0.315 left) and INCIDENTDESC (0.315) are near-complete and were scheduled nowhere. Close both. | G7: Both at 100% on the Priority Board. | H7: Not started | I7: ;INCIDENT;INCIDENTDESC; | J7: -
A8: 2026-09-30 | B8: Wed | C8: 10:00 - 14:00 | D8: Code | E8: INCIDENTFC | F8: Validation: confirm the holdout window, that the champion was selected on held-out data, and that the baseline comparison is honest. | G8: The model's metrics are reproducible from a script. | H8: Not started | I8: ;INCIDENTFC; | J8: -
C9: 14:00 - 20:30 | D9: Code | E9: INCIDENTFC | F9: Close the remaining subtasks. | G9: INCIDENTFC approaching 100%. | H9: Not started | I9: ;INCIDENTFC; | J9: -
C10: 20:30 - 22:30 | D10: Manuscript | E10: MS-01 INCIDENT | F10: Document the incident API endpoints - routes, payloads, filters. | G10: Section complete. | H10: Not started | I10: ;MOD-BE; | J10: ;MS:INCIDENT;
A11: 2026-10-01 | B11: Thu | C11: 10:00 - 14:00 | D11: Code | E11: INCIDENTFC | F11: Finish and sign off. | G11: INCIDENTFC at 100%. | H11: Not started | I11: ;INCIDENTFC; | J11: -
C12: 14:00 - 19:30 | D12: Code | E12: MAPCOMP | F12: Start the Map Comparison API remaining subtasks. | G12: Progress on MAPCOMP. | H12: Not started | I12: ;MAPCOMP; | J12: -
C13: 19:30 - 22:30 | D13: Manuscript | E13: MS-01 INCIDENTDESC | F13: Document the incident descriptive analytics - the cause split, the severity ladder, the response-time breakdown. | G13: Section complete. | H13: Not started | I13: ;MOD-ANA; | J13: ;MS:INCIDENTDESC;
A14: 2026-10-02 | B14: Fri | C14: 10:00 - 14:00 | D14: Code | E14: MAPCOMP | F14: Close Map Comparison. | G14: MAPCOMP at 100%. | H14: Not started | I14: ;MAPCOMP; | J14: -
C15: 14:00 - 19:30 | D15: Code | E15: AUDIT | F15: Start the Audit Log API subtasks. | G15: Progress on AUDIT. | H15: Not started | I15: ;AUDIT; | J15: -
C16: 19:30 - 22:30 | D16: Manuscript | E16: MS-01 INCIDENTFC | F16: Document the incident prediction model: Poisson GLM champion, the walk-forward design, and the metrics. | G16: Section complete with real numbers. | H16: Not started | I16: ;MOD-ANA; | J16: ;MS:INCIDENTFC;
A17: 2026-10-03 | B17: Sat | C17: 10:00 - 14:00 | D17: Code | E17: AUDIT | F17: Close the Audit Log API. | G17: AUDIT at 100%. | H17: Not started | I17: ;AUDIT; | J17: -
C18: 14:00 - 18:30 | D18: Code | E18: Ch4 figure decisions | F18: Same call for the prescriptive items: no LP toll-lane optimizer (4.1.24), no variable speed limit (4.1.25), no weather/surge alert panel (4.1.26), no TOPSIS ranking (4.1.28). The draft already notes these - decide keep / retitle / drop. | G18: Each figure is decided and the caption matches the build. | H18: Not started | I18: ;MANUSCRIPT; | J18: ;C09;
C19: 18:30 - 22:30 | D19: Manuscript | E19: 3.13 SQA Plans | F19: Revise 3.13 (p219). The plan claims a linting step that has never executed - ESLint could not run until Kiarra migrated the config today. Describe the QA process that actually happens. | G19: 3.13 describes real practice, not intended practice. | H19: Not started | I19: ;MANUSCRIPT; | J19: ;R08;
A20: GATE 21:00 - the 0% tasks demoable
A21: 2026-10-04 | B21: Sun | C21: 10:00 - 14:00 | D21: Code | E21: AGENT (scenarios) | F21: Your half of the agent simulation: the incident side. Walk every family in ai-sandbox/scenarios/catalogue.ts - breakdown in lane, breakdown on shoulder, minor collision, multi-vehicle, self accident, overturned vehicle, flood, roadworks, rain - and confirm each has a real duration distribution behind it rather than a guessed constant. | G21: Every family duration and lane-blocking rule traces to observed data, or is labelled in the UI as an assumption. | H21: Not started | I21: ;AGENT-S; | J21: -
C22: 14:00 - 18:30 | D22: Code | E22: AGENT (validation) | F22: Validate what the simulation does when an incident lands, against what actually happens on NLEX. Compare sim time-to-clear with the Cox PH clearance model and the observed incident log. Then QA the replication machinery: the intervals are Student t at 95% over N runs, so check N is large enough for the interval to mean anything. | G22: A short validation note states how sim clearance compares with observed, and the replication count is justified. | H22: Not started | I22: ;AGENT-S; | J22: -
C23: 18:30 - 22:30 | D23: Manuscript | E23: MS-01 AGENT | F23: Document the agent-based simulation with Hans: IDM and MOBIL, the calibration source, the scenario families, and - just as important - what the sandbox does NOT claim to predict. | G23: Section written, and honest about scope. | H23: Not started | I23: ;MOD-ANA; | J23: ;MS:AGENT;
A24: 2026-10-05 | B24: Mon | C24: 10:00 - 14:00 | D24: Code | E24: QA | F24: Set up defect tracking - where defects are logged, severity definitions, who retests - then begin the regression pass on everything frozen so far. | G24: Defect log exists and half the test plan is executed. | H24: Not started | I24: (overhead) | J24: -
C25: 14:00 - 16:30 | D25: Code | E25: QA | F25: Continue the regression pass across Traffic, Incidents, Emissions, Map Comparison and the Sandbox. | G25: Defects logged with severity and owner. | H25: Not started | I25: (overhead) | J25: -
C26: 16:30 - 22:30 | D26: Manuscript | E26: MS-01 MAPCOMP + 2.3 | F26: Document the map comparison API, then a light pass on 2.3 Synthesis (p114) - check nothing there leans on a figure that changed during development. | G26: Section written; synthesis consistent with the corrected numbers. | H26: Not started | I26: ;MOD-BE; | J26: ;R12;MS:MAPCOMP;
A27: 2026-10-06 | B27: Tue | C27: 10:00 - 14:00 | D27: Code | E27: 4.3 Testing | F27: Run the Unit, Stress and User-Acceptance scenarios from Section 3.13, and record the results as you go - this is the regression pass and the manuscript section in one. Note 6 of the draft says 4.3 is missing entirely. | G27: Every scenario in 3.13 has a run and a recorded result. | H27: Not started | I27: ;MANUSCRIPT; | J27: ;C11;
C28: 14:00 - 14:30 | D28: Code | E28: 4.3 Testing | F28: Continue, and start writing 4.3 from the results rather than from memory. | G28: 4.3 drafted against real runs. | H28: Not started | I28: ;MANUSCRIPT; | J28: ;C11;
C29: 14:30 - 22:30 | D29: Manuscript | E29: References | F29: Set up the citation style and check every reference resolves. This is the thing that eats Oct 8 if left. | G29: Reference list complete and consistently formatted. | H29: Not started | I29: ;MANUSCRIPT; | J29: -
A30: GATE 22:30 - SYSTEM 90%, CODE FREEZE
A31: 2026-10-07 | B31: Wed | C31: 10:00 - 14:00 | D31: Code | E31: 4.4 Discussion | F31: Draft 4.4: interpret the results against the four specific objectives from Section 1.4.2. Say plainly where coverage is partial - a panel trusts a stated limitation more than a claim it can puncture. | G31: 4.4 drafted, with each objective addressed and its gaps named. | H31: Not started | I31: ;MANUSCRIPT; | J31: ;C11;
C32: 14:00 - 12:30 | D32: Code | E32: 4.4 Discussion | F32: Finish 4.4 and retest anything the writing exposed - writing the discussion is usually where a gap in the evidence becomes obvious. | G32: 4.4 complete. | H32: Not started | I32: ;MANUSCRIPT; | J32: ;C11;
C33: 12:30 - 22:30 | D33: Manuscript | E33: Formatting | F33: Template compliance across the whole manuscript: margins, heading styles, caption numbering, table formats, pagination. | G33: The document matches the required template throughout. | H33: Not started | I33: ;MANUSCRIPT; | J33: -
A34: 2026-10-08 | B34: Thu | C34: 10:00 - 14:00 | D34: Code | E34: - | F34: No code today. | G34: - | H34: Not started | I34: (overhead) | J34: -
C35: 14:00 - 10:00 | D35: Code | E35: - | F35: No code today. | G35: - | H35: Not started | I35: (overhead) | J35: -
C36: 10:00 - 22:30 | D36: Manuscript | E36: Manuscript | F36: Final proofread and the appendices. You are the checker - this is your pass. Read for defensibility: does every claim have evidence behind it in the document. | G36: No unsupported claim survives, and the appendices are complete. | H36: Not started | I36: ;MANUSCRIPT; | J36: -
A37: GATE 20:00 - manuscript complete

Sheet Ysa
A1: Ysa - daily plan
A2: Three blocks a day. Code from 10:00; the manuscript takes the tail. Column F is what to do, column G is how you know it is finished. Ticking Status = Done credits the task named in Feeds - so the Tracker moves as you work. Blocks marked (overhead) carry no weight in the acceptance criteria.
A4: Date | B4: Day | C4: Block | D4: Track | E4: Task | F4: What to do | G4: Done when | H4: Status | I4: Feeds | J4: Closes
A5: 2026-09-29 | B5: Tue | C5: 10:00 - 14:00 | D5: Code | E5: LLM audit | F5: RAG is not greenfield - the LLM layer is already built. Read lib/glm.client.ts, services/ai-insight.service.ts, ai-explain.service.ts and sandbox-command.service.ts, then map each of RAG's six subtasks (BUS-01, DU-01, DP-01, MODEL-01, DEV-01, DEV-02) to what exists and what does not. | G5: A six-row table showing, per subtask, built / partly built / not built - ready for the team to decide scope. | H5: Not started | I5: ;RAG; | J5: -
C6: 14:00 - 20:30 | D6: Code | E6: LLM evidence | F6: Capture the evidence for what IS built: the sandbox Command prompt turning a sentence into actions, and an AI Explain briefing on a descriptive tab. Note that ai-explain retrieves from the warehouse server-side and grounds the prompt - that is retrieval-augmented generation over data, even though the criteria describe it over documents. | G6: Screenshots and a short note on how grounding is enforced, ready for the manuscript. | H6: Not started | I6: ;RAG; | J6: -
C7: 20:30 - 22:30 | D7: Manuscript | E7: MS-01 RAG | F7: Document the LLM integration: GLM via an OpenAI-compatible endpoint, the three services and what each grounds on, and the deviation from the criteria (Claude Sonnet / FastAPI / vector index specified; GLM / Express / warehouse retrieval delivered). Use the same convention as Figures 4.1.9, 4.1.24 and 4.1.28. | G7: Section written, with the deviation stated rather than glossed. | H7: Not started | I7: ;MOD-ANA; | J7: ;C03;MS:RAG;
A8: 2026-09-30 | B8: Wed | C8: 10:00 - 14:00 | D8: Code | E8: SANDBOX | F8: Close the AI Traffic Sandbox API subtasks. Pulled forward two days now that RAG is not three days of building. | G8: SANDBOX at 100%. | H8: Not started | I8: ;SANDBOX; | J8: -
C9: 14:00 - 20:30 | D9: Code | E9: SANDBOX | F9: Test the sandbox end to end from the dashboard. Hand Hans and Jertz a working API to calibrate against - they start on the simulation model Oct 4. | G9: A scenario can be built, run and read from the UI, and the two model owners can drive it without you. | H9: Not started | I9: ;SANDBOX; | J9: -
C10: 20:30 - 22:30 | D10: Manuscript | E10: MS-01 SANDBOX | F10: Document the sandbox API. The simulation model itself is Hans and Jertz's section. | G10: Section complete. | H10: Not started | I10: ;MOD-BE; | J10: ;MS:SANDBOX;
A11: 2026-10-01 | B11: Thu | C11: 10:00 - 14:00 | D11: Code | E11: REALTIME | F11: Close the Redis realtime and event streaming subtasks. | G11: REALTIME at 100%. | H11: Not started | I11: ;REALTIME; | J11: -
C12: 14:00 - 19:30 | D12: Code | E12: REALTIME | F12: Test the streaming path end to end, including what the dashboard does when Redis is unavailable. | G12: REALTIME at 100% and the failure mode is documented. | H12: Not started | I12: ;REALTIME; | J12: -
C13: 19:30 - 22:30 | D13: Manuscript | E13: MS-01 REALTIME | F13: Document the real-time architecture - what streams, through what, and what happens when Redis is down. | G13: Section complete. | H13: Not started | I13: ;MOD-BE; | J13: ;MS:REALTIME;
A14: 2026-10-02 | B14: Fri | C14: 10:00 - 14:00 | D14: Code | E14: UPLOAD | F14: Close the Data Upload and Validation API subtasks. | G14: UPLOAD at 100%. | H14: Not started | I14: ;UPLOAD; | J14: -
C15: 14:00 - 19:30 | D15: Code | E15: UPLOAD | F15: Test upload validation with four files: a good one, a malformed one, one with the wrong columns, and an empty one. | G15: All four behave, and none corrupts the warehouse. | H15: Not started | I15: ;UPLOAD; | J15: -
C16: 19:30 - 22:30 | D16: Manuscript | E16: MS-01 UPLOAD | F16: Document the upload API and its validation rules. | G16: Section complete. | H16: Not started | I16: ;MOD-BE; | J16: ;MS:UPLOAD;
A17: 2026-10-03 | B17: Sat | C17: 10:00 - 14:00 | D17: Code | E17: LLM sign-off | F17: RAG is descoped - the LLM layer replaces it. Get that confirmed in writing by the adviser, because RAG carries 2.517% in the acceptance file and the substitution has to be accepted, not assumed. Then update the acceptance file yourselves: mark RAG as delivered-by-other-means rather than leaving it at 0.000%. | G17: A written reply from the adviser, and the acceptance file no longer shows RAG as simply not started. | H17: Not started | I17: ;RAG; | J17: -
C18: 14:00 - 18:30 | D18: Code | E18: SANDBOX handover | F18: Hans and Jertz start on the simulation model tomorrow and will drive it through your API. Walk them through it, and fix anything that blocks them running a scenario without you. | G18: Both can run and read a scenario unaided. | H18: Not started | I18: ;SANDBOX; | J18: -
C19: 18:30 - 22:30 | D19: Manuscript | E19: Figures | F19: Start the Chapter 4 screenshots for your surfaces: sandbox UI, the Command prompt turning a sentence into actions, upload page, realtime panels. Light theme, full resolution, no dev overlay. | G19: Half your figures captured and named. | H19: Not started | I19: (overhead) | J19: -
A20: GATE 21:00 - the 0% tasks demoable
A21: 2026-10-04 | B21: Sun | C21: 10:00 - 14:00 | D21: Code | E21: Mobile | F21: Mobile parity check against /api/mobile-config. The mobile app is a separate repo (SmartFlow-NLEX/Main-Mobile) - confirm it still runs against the current backend and shows current data. | G21: The mobile app loads live data from the deployed backend. | H21: Not started | I21: (overhead) | J21: -
C22: 14:00 - 18:30 | D22: Code | E22: MOD-FE support | F22: Take UI work off Kiarra. She owns CORE (production build, ESLint, deployment) plus the whole MOD-FE polish list; you are the other UI/UX pair of hands and she is the bottleneck on two fronts. | G22: Kiarra's snag list is shorter and she is free to work CORE. | H22: Not started | I22: (overhead) | J22: -
C23: 18:30 - 22:30 | D23: Manuscript | E23: Figures | F23: Finish your figures and hand them to Kiarra for placement. | G23: All figures delivered. | H23: Not started | I23: (overhead) | J23: -
A24: 2026-10-05 | B24: Mon | C24: 10:00 - 14:00 | D24: Code | E24: Slack | F24: Deliberate slack, two days ahead of the original plan. Spend it wherever the Oct 3 gate slipped - most likely Jertz on INCIDENTFC or Hans on PRESCRIBE, the two biggest zeros. If nothing slipped, take more of Kiarra's MOD-FE list. | G24: The team's worst-off task moved, or Kiarra's list is empty. | H24: Not started | I24: (overhead) | J24: -
C25: 14:00 - 16:30 | D25: Code | E25: MOD-FE support | F25: Continue with Kiarra. | G25: MOD-FE closer to done. | H25: Not started | I25: (overhead) | J25: -
C26: 16:30 - 22:30 | D26: Manuscript | E26: Figures | F26: Any remaining captures, including anything Hans or Jertz need for their sections. | G26: No figure outstanding from your surfaces. | H26: Not started | I26: (overhead) | J26: -
A27: 2026-10-06 | B27: Tue | C27: 10:00 - 14:00 | D27: Code | E27: Close out | F27: Close every remaining subtask you own. Last day for code. | G27: All your tasks at 100%. | H27: Not started | I27: (overhead) | J27: -
C28: 14:00 - 14:30 | D28: Code | E28: FREEZE | F28: Freeze with the team. | G28: Nothing of yours merges after 22:30. | H28: Not started | I28: (overhead) | J28: -
C29: 14:30 - 22:30 | D29: Manuscript | E29: Ch4 reconciliation | F29: Recapture the figures that no longer match the build, working from the Chapter 4 block on the Manuscript Revisions sheet. Hand each to the owner named there. | G29: Every figure marked Critical or High has a current capture. | H29: Not started | I29: ;MANUSCRIPT; | J29: ;C01;
A30: GATE 22:30 - SYSTEM 90%, CODE FREEZE
A31: 2026-10-07 | B31: Wed | C31: 10:00 - 14:00 | D31: Code | E31: FIX | F31: Defects from Jertz on your surfaces. | G31: Your defect list is empty. | H31: Not started | I31: (overhead) | J31: -
C32: 14:00 - 12:30 | D32: Code | E32: FIX | F32: Continue. | G32: Queue empty. | H32: Not started | I32: (overhead) | J32: -
C33: 12:30 - 22:30 | D33: Manuscript | E33: Ch4 reconciliation | F33: Finish the recaptures and place them with their captions. | G33: No figure in Chapter 4 predates the code freeze. | H33: Not started | I33: ;MANUSCRIPT; | J33: ;C02;
A34: 2026-10-08 | B34: Thu | C34: 10:00 - 14:00 | D34: Code | E34: - | F34: No code today. | G34: - | H34: Not started | I34: (overhead) | J34: -
C35: 14:00 - 10:00 | D35: Code | E35: - | F35: No code today. | G35: - | H35: Not started | I35: (overhead) | J35: -
C36: 10:00 - 22:30 | D36: Manuscript | E36: Manuscript | F36: Support the final read. Check every section describing something you built actually matches it. | G36: Your sections are verified against the frozen build. | H36: Not started | I36: ;MANUSCRIPT; | J36: -
A37: GATE 20:00 - manuscript complete

Sheet Manuscript
A1: Manuscript - 10% of the grade, currently 0.769%
A2: Weight is allocated per module. Put Y in Done? to count a module's manuscript block in full, or a partial figure in Actual %. The 26 subtasks below are the checklist behind it.
A4: A. WEIGHT BY MODULE
A5: Module | B5: What it documents | D5: Owner | E5: Alloc % | F5: Actual % | G5: Points to gain | H5: % done | I5: Status | J5: Done? | K5: Blocks done | L5: Blocks planned
A6: MOD-BE | B6: Every backend API section in Chapter 4 | D6: Jertz | E6: 2.564103 | F6: 0 | G6: =E6-(IF(UPPER(J6)="Y",E6,IF(L6=0,F6,F6+(E6-F6)*K6/L6))) | H6: =IFERROR((IF(UPPER(J6)="Y",E6,IF(L6=0,F6,F6+(E6-F6)*K6/L6)))/E6,0) | I6: =IF((IF(UPPER(J6)="Y",E6,IF(L6=0,F6,F6+(E6-F6)*K6/L6)))>=E6,"Done",IF((IF(UPPER(J6)="Y",E6,IF(L6=0,F6,F6+(E6-F6)*K6/L6)))>0,"In progress","Not started")) | J6: N | K6: =COUNTIFS(Kiarra!$I:$I,"*;"&$A6&";*",Kiarra!$H:$H,"Done")+COUNTIFS(Hans!$I:$I,"*;"&$A6&";*",Hans!$H:$H,"Done")+COUNTIFS(Jertz!$I:$I,"*;"&$A6&";*",Jertz!$H:$H,"Done")+COUNTIFS(Ysa!$I:$I,"*;"&$A6&";*",Ysa!$H:$H,"Done") | L6: =COUNTIF(Kiarra!$I:$I,"*;"&$A6&";*")+COUNTIF(Hans!$I:$I,"*;"&$A6&";*")+COUNTIF(Jertz!$I:$I,"*;"&$A6&";*")+COUNTIF(Ysa!$I:$I,"*;"&$A6&";*")
